<mujoco>
<option gravity="0 0 0" />
 <default>
    <default class="left_hand">
      <mesh scale="0.001 0.001 0.001"/>
      <joint axis="1 0 0" damping="0.05" armature="0.0002" frictionloss="0.01"/>
      <position forcerange="-1 1"/>

      <default class="wrist">
        <joint damping="0.5"/>
        <default class="wrist_y">
          <joint axis="0 -1 0" range="-0.523599 0.174533"/>
          <position kp="10" ctrlrange="-0.523599 0.174533" forcerange="-10 10"/>
        </default>
        <default class="wrist_x">
          <joint range="-0.698132 0.488692"/>
          <position kp="8" ctrlrange="-0.698132 0.488692" forcerange="-5 5"/>
        </default>
      </default>
	</default>
	<default class="plastic">
        <geom solimp="0.5 0.99 0.0001" solref="0.005 1"/>
        <default class="plastic_visual">
          <geom type="mesh" material="black" contype="0" conaffinity="0" group="2"/>
        </default>
        <default class="plastic_collision">
          <geom group="3"/>
        </default>
      </default>
</default>


<asset>
    <material name="blue" specular="0.5" shininess="0.25" rgba="0.2 0.2 0.8 1"/>
    <material name="gray" specular="0.0" shininess="0.25" rgba="0.80848 0.80848 0.80848 1"/>
    <material name="white" specular="0" shininess="0.25" rgba="1 1 1 1"/>

    <!-- Palm -->
    <mesh name="hand_palm" file="assets/handPalm.obj" scale="-0.01 0.01 0.01" />

    <!-- Index Finger -->
    <mesh name="index_female" file="assets/fingers/index/female_index.stl" scale="-0.01 0.01 0.01" />
    <mesh name="index_part12" file="assets/fingers/index/part1_2_index.stl" scale="-0.01 0.01 0.01" />
    <mesh name="index_part3" file="assets/fingers/index/part3_index.stl" scale="-0.01 0.01 0.01" />
    <mesh name="index_part4" file="assets/fingers/index/part4_index.stl" scale="-0.01 0.01 0.01" />
    <mesh name="index_part5" file="assets/fingers/index/part5_index.stl" scale="-0.01 0.01 0.01" />
    <mesh name="index_tip" file="assets/fingers/index/tip_index.stl" scale="-0.01 0.01 0.01" />

    <!-- Middle Finger -->
    <mesh name="middle_part12" file="assets/fingers/middle/part1_2_middle.stl" scale="-0.01 0.01 0.01" />
    <mesh name="middle_female" file="assets/fingers/middle/female_middle.stl" scale="-0.01 0.01 0.01" />
    <mesh name="middle_part3" file="assets/fingers/middle/part3_middle.stl" scale="-0.01 0.01 0.01" />
    <mesh name="middle_part4" file="assets/fingers/middle/part4_middle.stl" scale="-0.01 0.01 0.01" />
    <mesh name="middle_part5" file="assets/fingers/middle/part5_middle.stl" scale="-0.01 0.01 0.01" />
    <mesh name="middle_tip" file="assets/fingers/middle/tip_middle.stl" scale="-0.01 0.01 0.01" />

    <!-- Ring Finger -->
    <mesh name="ring_part12" file="assets/fingers/ring/part1_2_ring.stl" scale="-0.01 0.01 0.01" />
    <mesh name="ring_female" file="assets/fingers/ring/female_ring.stl" scale="-0.01 0.01 0.01" />
    <mesh name="ring_part3" file="assets/fingers/ring/part3_ring.stl" scale="-0.01 0.01 0.01" />
    <mesh name="ring_part4" file="assets/fingers/ring/part4_ring.stl" scale="-0.01 0.01 0.01" />
    <mesh name="ring_part5" file="assets/fingers/ring/part5_ring.stl" scale="-0.01 0.01 0.01" />
    <mesh name="ring_tip" file="assets/fingers/ring/tip_ring.stl" scale="-0.01 0.01 0.01" />

    <!-- Pinky Finger -->
    <mesh name="pinky_part12" file="assets/fingers/pinky/part1_2_pinky.stl" scale="-0.01 0.01 0.01" />
    <mesh name="pinky_female" file="assets/fingers/pinky/female_pinky.stl" scale="-0.01 0.01 0.01" />
    <mesh name="pinky_part3" file="assets/fingers/pinky/part3_pinky.stl" scale="-0.01 0.01 0.01" />
    <mesh name="pinky_part4" file="assets/fingers/pinky/part4_pinky.stl" scale="-0.01 0.01 0.01" />
    <mesh name="pinky_part5" file="assets/fingers/pinky/part5_pinky.stl" scale="-0.01 0.01 0.01" />
    <mesh name="pinky_tip" file="assets/fingers/pinky/tip_pinky.stl" scale="-0.01 0.01 0.01" />

    <!-- Thumb Finger -->
    <mesh name="thumb_part12" file="assets/fingers/thumb/part1_2_thumb.stl" scale="-0.01 0.01 0.01" />
    <mesh name="thumb_female" file="assets/fingers/thumb/female_thumb.stl" scale="-0.01 0.01 0.01" />
    <mesh name="thumb_part3" file="assets/fingers/thumb/part3_thumb.stl" scale="-0.01 0.01 0.01" />
    <!-- <mesh name="thumb_part4" file="assets/fingers/thumb/part4_thumb.stl" scale="-0.01 0.01 0.01" />
    <mesh name="thumb_part5" file="assets/fingers/thumb/part5_thumb.stl" scale="-0.01 0.01 0.01" /> -->
    <mesh name="thumb_tip" file="assets/fingers/thumb/tip_thumb.stl" scale="-0.01 0.01 0.01" />

  </asset>

<worldbody>
    <light diffuse=".5 .5 .5" pos="0 0 3" dir="0 0 -1"/>
		<geom type="plane" size="10 10 0.1" rgba=".0 .9 .9 1"/>
		<!-- Palm -->
    <body name="palm">
      <geom type="mesh" mesh="hand_palm" material="white" euler="0 90 0" pos="0 0 1"/>
    </body>

    <!-- Index Finger -->
    <body euler="-90 0 -84" pos="-0.2 0.1 1.475">
      <joint type="hinge" axis="-1 0 0" pos="0.04 0.18 0" limited="true" range="-90 90" damping="0.3"/>
      <body name="index_finger">
        <geom type="mesh" mesh="index_female" material="blue" pos="0.005 0 0" />
      </body>
      <geom type="mesh" mesh="index_part12" material="blue" pos="0.005 0 0" euler="180 180 0" />
      <body>
        <joint type="hinge" axis="-1 0 0" pos="0.05 -0.18 0" limited="true" range="-90 90" damping="0.3"/>
        <geom type="mesh" mesh="index_part3" material="blue" pos="0.005 -0.32 0" euler="0 -90 0"  />
        <geom type="mesh" mesh="index_part4" material="blue" pos="0.005 -0.3 0" euler="180 180 0" />
        <body>
          <joint type="hinge" axis="-1 0 0" pos="0.05 -0.47 0" limited="true" range="-90 90" damping="0.3"/>
          <geom type="mesh" mesh="index_part5" material="blue" pos="0.005 -0.6 0" euler="0 -90 0" />
          <geom type="mesh" mesh="index_tip" material="gray" pos="0.005 -0.6 0" euler="180 180 0" />
        </body>
      </body>
    </body>

    <!-- Middle Finger -->
    <body euler="90 0 -90" pos="-0.2 0.1 1.23">
      <joint type="hinge" axis="-1 0 0" pos="0.04 0.18 0" limited="true" range="-90 90" damping="0.3"/>
      <body name="middle_finger">
        <geom type="mesh" mesh="middle_female" material="blue" pos="0.005 0 0"  euler="0 180 0"/>
      </body>
      <geom type="mesh" mesh="middle_part12" material="blue" pos="0.005 0 0"  euler="180 0 0" /> 
      <body>
        <joint type="hinge" axis="-1 0 0" pos="0.05 -0.18 0" limited="true" range="-90 90" damping="0.3"/>
        <geom type="mesh" mesh="middle_part3" material="blue" pos="0.005 -0.32 0" euler="0 90 0" />
        <geom type="mesh" mesh="middle_part4" material="blue" pos="0.005 -0.3 0"  euler="180 0 0" />
        <body>
          <joint type="hinge" axis="-1 0 0" pos="0.05 -0.47 0" limited="true" range="-90 90" damping="0.3"/>
          <geom type="mesh" mesh="middle_part5" material="blue" pos="0.005 -0.6 0" euler="0 90 0" />
          <geom type="mesh" mesh="middle_tip" material="gray" pos="0.005 -0.6 0"  euler="180 0 0" />
        </body>
      </body> 
    </body>

    <!-- Ring Finger -->
    <body euler="90 0 -85" pos="-0.2 0.1 0.975">
      <joint type="hinge" axis="-1 0 0" pos="0.04 0.18 0" limited="true" range="-90 90" damping="0.3"/>
      <body name="ring_finger">
        <geom type="mesh" mesh="middle_female" material="blue" pos="0.005 0 0"  euler="0 180 0"/>
      </body>
      <geom type="mesh" mesh="middle_part12" material="blue" pos="0.005 0 0"  euler="180 0 0" /> 
      <body>
        <joint type="hinge" axis="-1 0 0" pos="0.05 -0.18 0" limited="true" range="-90 90" damping="0.3"/>
        <geom type="mesh" mesh="middle_part3" material="blue" pos="0.005 -0.32 0" euler="0 90 0" />
        <geom type="mesh" mesh="middle_part4" material="blue" pos="0.005 -0.3 0"  euler="180 0 0" />
        <body>
          <joint type="hinge" axis="-1 0 0" pos="0.05 -0.47 0" limited="true" range="-90 90" damping="0.3"/>
          <geom type="mesh" mesh="middle_part5" material="blue" pos="0.005 -0.6 0" euler="0 90 0" />
          <geom type="mesh" mesh="middle_tip" material="gray" pos="0.005 -0.6 0"  euler="180 0 0" />
        </body>
      </body> 
    </body>

    <!-- Pinky Finger -->
    <body euler="90 0 -80" pos="-0.2 0.1 0.725">
      <joint type="hinge" axis="-1 0 0" pos="0.04 0.18 0" limited="true" range="-90 90" damping="0.3"/>
      <body name="pinky_finger">
        <geom type="mesh" mesh="pinky_female" material="blue" pos="0.005 0 0"  euler="0 180 0"/>
      </body>
      <geom type="mesh" mesh="pinky_part12" material="blue" pos="0.005 0 0"  euler="180 0 0" /> 
      <body>
        <joint type="hinge" axis="-1 0 0" pos="0.05 -0.18 0" limited="true" range="-90 90" damping="0.3"/>
        <geom type="mesh" mesh="pinky_part3" material="blue" pos="0.005 -0.32 0" euler="0 90 0" />
        <geom type="mesh" mesh="pinky_part4" material="blue" pos="0.005 -0.3 0"  euler="180 0 0" />
        <body>
          <joint type="hinge" axis="-1 0 0" pos="0.05 -0.47 0" limited="true" range="-90 90" damping="0.3"/>
          <geom type="mesh" mesh="pinky_part5" material="blue" pos="0.005 -0.6 0" euler="0 90 0" />
          <geom type="mesh" mesh="pinky_tip" material="gray" pos="0.005 -0.6 0"  euler="180 0 0" />
        </body>
      </body> 
    </body>

    <!-- Thumb Finger -->
    <body euler="90 0 150" pos="0.875 0.1 1.675">
      <joint type="hinge" axis="-1 0 0" pos="0.04 0.18 0" limited="true" range="-90 90" damping="0.3"/>
      <body name="thumb_finger">
        <geom type="mesh" mesh="thumb_female" material="blue" pos="0.005 0 0"  euler="0 180 0"/>
      </body>
      <geom type="mesh" mesh="thumb_part12" material="blue" pos="0.005 0 0"  euler="180 0 0" /> 
      <body>
        <joint type="hinge" axis="-1 0 0" pos="0.05 -0.18 0" limited="true" range="-90 90" damping="0.3"/>
        <geom type="mesh" mesh="thumb_part3" material="blue" pos="0.005 -0.32 0" euler="0 90 0" />
        <geom type="mesh" mesh="thumb_tip" material="gray" pos="0.005 -0.3 0"  euler="180 0 0" />
      </body> 
    </body>
	</worldbody>

  <contact>
        <exclude name="exclude_palm_2_index" body1="palm" body2="index_finger"/>
        <exclude name="exclude_palm_2_middle" body1="palm" body2="middle_finger"/>
        <exclude name="exclude_palm_2_ring" body1="palm" body2="ring_finger"/>
        <exclude name="exclude_palm_2_pinky" body1="palm" body2="pinky_finger"/>
        <exclude name="exclude_palm_2_thumb" body1="palm" body2="thumb_finger"/>
  </contact>
</mujoco>
